[0m15:49:22.794209 [debug] [MainThread]: Sending event: {'category': 'dbt', 'action': 'invocation', 'label': 'start', 'context': [<snowplow_tracker.self_describing_json.SelfDescribingJson object at 0x7facfd8fcd50>, <snowplow_tracker.self_describing_json.SelfDescribingJson object at 0x7facfd8fc790>, <snowplow_tracker.self_describing_json.SelfDescribingJson object at 0x7facfd8fc7d0>]}


============================== 15:49:22.797995 | 8beea7d7-1b95-49c5-966e-de7db6b207f7 ==============================
[0m15:49:22.797995 [info ] [MainThread]: Running with dbt=1.5.8
[0m15:49:22.799104 [debug] [MainThread]: running dbt with arguments {'cache_selected_only': 'False', 'log_cache_events': 'False', 'warn_error': 'None', 'log_format': 'default', 'printer_width': '80', 'warn_error_options': 'WarnErrorOptions(include=[], exclude=[])', 'log_path': 'logs', 'write_json': 'True', 'fail_fast': 'False', 'send_anonymous_usage_stats': 'True', 'quiet': 'False', 'use_colors': 'True', 'static_parser': 'True', 'no_print': 'None', 'version_check': 'True', 'target_path': 'None', 'debug': 'False', 'indirect_selection': 'eager', 'profiles_dir': '/Users/rapido/.dbt', 'partial_parse': 'True', 'use_experimental_parser': 'False', 'introspect': 'True'}
[0m15:49:22.799948 [warn ] [MainThread]: [ConfigFolderDirectory]: Unable to parse dict {'dir': PosixPath('/Users/rapido/.dbt')}
[0m15:49:22.800538 [info ] [MainThread]: Creating dbt configuration folder at 
[0m15:49:22.801775 [error] [MainThread]: Encountered an error:
1
[0m15:49:22.803181 [error] [MainThread]: Traceback (most recent call last):
  File "/Users/rapido/Documents/GitHub/Marketing-Analytics-Solution-Using-Fivetran-and-dbt/dbt-env/lib/python3.7/site-packages/dbt/cli/requires.py", line 86, in wrapper
    result, success = func(*args, **kwargs)
  File "/Users/rapido/Documents/GitHub/Marketing-Analytics-Solution-Using-Fivetran-and-dbt/dbt-env/lib/python3.7/site-packages/dbt/cli/requires.py", line 71, in wrapper
    return func(*args, **kwargs)
  File "/Users/rapido/Documents/GitHub/Marketing-Analytics-Solution-Using-Fivetran-and-dbt/dbt-env/lib/python3.7/site-packages/dbt/cli/main.py", line 475, in init
    results = task.run()
  File "/Users/rapido/Documents/GitHub/Marketing-Analytics-Solution-Using-Fivetran-and-dbt/dbt-env/lib/python3.7/site-packages/dbt/task/init.py", line 287, in run
    sys.exit(1)
SystemExit: 1

[0m15:49:22.804275 [debug] [MainThread]: Command `dbt init` failed at 15:49:22.804036 after 0.03 seconds
[0m15:49:22.804841 [debug] [MainThread]: Sending event: {'category': 'dbt', 'action': 'invocation', 'label': 'end', 'context': [<snowplow_tracker.self_describing_json.SelfDescribingJson object at 0x7facfd8fc550>, <snowplow_tracker.self_describing_json.SelfDescribingJson object at 0x7facfd934f90>, <snowplow_tracker.self_describing_json.SelfDescribingJson object at 0x7facfd934fd0>]}
[0m15:49:22.805533 [debug] [MainThread]: Flushing usage events
[0m15:57:49.896786 [debug] [MainThread]: Sending event: {'category': 'dbt', 'action': 'invocation', 'label': 'start', 'context': [<snowplow_tracker.self_describing_json.SelfDescribingJson object at 0x7f856e871dd0>, <snowplow_tracker.self_describing_json.SelfDescribingJson object at 0x7f856e871f50>, <snowplow_tracker.self_describing_json.SelfDescribingJson object at 0x7f856e871fd0>]}


============================== 15:57:49.899747 | b177b5dc-dc4a-4939-ae34-a46db78e9909 ==============================
[0m15:57:49.899747 [info ] [MainThread]: Running with dbt=1.5.1
[0m15:57:49.900506 [debug] [MainThread]: running dbt with arguments {'static_parser': 'True', 'version_check': 'True', 'quiet': 'False', 'log_path': 'logs', 'log_format': 'default', 'no_print': 'None', 'target_path': 'None', 'warn_error_options': 'WarnErrorOptions(include=[], exclude=[])', 'send_anonymous_usage_stats': 'True', 'cache_selected_only': 'False', 'indirect_selection': 'eager', 'partial_parse': 'True', 'use_colors': 'True', 'warn_error': 'None', 'fail_fast': 'False', 'log_cache_events': 'False', 'write_json': 'True', 'printer_width': '80', 'debug': 'False', 'use_experimental_parser': 'False', 'introspect': 'True', 'profiles_dir': '/Users/rapido/.dbt'}
[0m15:58:50.098101 [debug] [MainThread]: Starter project path: /Users/rapido/Documents/GitHub/Marketing-Analytics-Solution-Using-Fivetran-and-dbt/dbt-env/lib/python3.7/site-packages/dbt/include/starter_project
[0m16:14:18.293302 [error] [MainThread]: Encountered an error:

[0m16:14:18.295430 [error] [MainThread]: Traceback (most recent call last):
  File "/Users/rapido/Documents/GitHub/Marketing-Analytics-Solution-Using-Fivetran-and-dbt/dbt-env/lib/python3.7/site-packages/dbt/cli/requires.py", line 86, in wrapper
    result, success = func(*args, **kwargs)
  File "/Users/rapido/Documents/GitHub/Marketing-Analytics-Solution-Using-Fivetran-and-dbt/dbt-env/lib/python3.7/site-packages/dbt/cli/requires.py", line 71, in wrapper
    return func(*args, **kwargs)
  File "/Users/rapido/Documents/GitHub/Marketing-Analytics-Solution-Using-Fivetran-and-dbt/dbt-env/lib/python3.7/site-packages/dbt/cli/main.py", line 457, in init
    results = task.run()
  File "/Users/rapido/Documents/GitHub/Marketing-Analytics-Solution-Using-Fivetran-and-dbt/dbt-env/lib/python3.7/site-packages/dbt/task/init.py", line 305, in run
    self.create_profile_from_target(adapter, profile_name=project_name)
  File "/Users/rapido/Documents/GitHub/Marketing-Analytics-Solution-Using-Fivetran-and-dbt/dbt-env/lib/python3.7/site-packages/dbt/task/init.py", line 180, in create_profile_from_target
    self.create_profile_from_profile_template(profile_template, profile_name)
  File "/Users/rapido/Documents/GitHub/Marketing-Analytics-Solution-Using-Fivetran-and-dbt/dbt-env/lib/python3.7/site-packages/dbt/task/init.py", line 164, in create_profile_from_profile_template
    target = self.generate_target_from_input(prompts, initial_target)
  File "/Users/rapido/Documents/GitHub/Marketing-Analytics-Solution-Using-Fivetran-and-dbt/dbt-env/lib/python3.7/site-packages/dbt/task/init.py", line 118, in generate_target_from_input
    profile_template_local[key][choice], target
  File "/Users/rapido/Documents/GitHub/Marketing-Analytics-Solution-Using-Fivetran-and-dbt/dbt-env/lib/python3.7/site-packages/dbt/task/init.py", line 131, in generate_target_from_input
    text, default=default, hide_input=hide_input, type=type
  File "/Users/rapido/Documents/GitHub/Marketing-Analytics-Solution-Using-Fivetran-and-dbt/dbt-env/lib/python3.7/site-packages/click/termui.py", line 164, in prompt
    value = prompt_func(prompt)
  File "/Users/rapido/Documents/GitHub/Marketing-Analytics-Solution-Using-Fivetran-and-dbt/dbt-env/lib/python3.7/site-packages/click/termui.py", line 147, in prompt_func
    raise Abort() from None
click.exceptions.Abort

[0m16:14:18.297215 [debug] [MainThread]: Command `dbt init` failed at 16:14:18.296996 after 988.42 seconds
[0m16:14:18.297775 [debug] [MainThread]: Sending event: {'category': 'dbt', 'action': 'invocation', 'label': 'end', 'context': [<snowplow_tracker.self_describing_json.SelfDescribingJson object at 0x7f856e884210>, <snowplow_tracker.self_describing_json.SelfDescribingJson object at 0x7f856e895250>, <snowplow_tracker.self_describing_json.SelfDescribingJson object at 0x7f856e895290>]}
[0m16:14:18.298336 [debug] [MainThread]: Flushing usage events
